<?xml version="1.0" ?>
<!-- =================================================================================== -->
<!-- |    This document was autogenerated by xacro from /home/mohammadabedi/Documents/Autonomous Scooter/Simulation/Gazebo/src/goal_marker_description/models/goal_marker/urdf/goal_marker.urdf.xacro | -->
<!-- |    EDITING THIS FILE BY HAND IS NOT RECOMMENDED                                 | -->
<!-- =================================================================================== -->
<robot name="goal_marker">
  <!-- Specify some standard inertial calculations https://en.wikipedia.org/wiki/List_of_moments_of_inertia -->
  <!-- These make use of xacro's mathematical functionality -->
  <!-- NOTE: do NOT declare pkg_uri here; it is passed in from launch via xacro.process_file(mappings=...) -->
  <!-- Root -->
  <link name="base_link"/>
  <!-- Chassis -->
  <link name="chassis">
    <visual name="chassis_visual">
      <origin xyz="0.4 0 0.75"/>
      <geometry>
        <box size="0.8 0.3 1.5"/>
      </geometry>
      <!-- simple fallback color; Gazebo script applies actual texture -->
      <material name="fallback_green">
        <color rgba="0 1 0 1"/>
      </material>
    </visual>
    <collision>
      <origin xyz="0.4 0 0.75"/>
      <geometry>
        <box size="0.8 0.3 1.5"/>
      </geometry>
    </collision>
    <inertial>
      <origin rpy="0 0 0" xyz="0.4 0 0.75"/>
      <mass value="0.5"/>
      <inertia ixx="0.09749999999999999" ixy="0.0" ixz="0.0" iyy="0.12041666666666667" iyz="0.0" izz="0.030416666666666668"/>
    </inertial>
  </link>
  <!-- Wheels -->
  <link name="left_wheel">
    <visual>
      <geometry>
        <cylinder length="0.04" radius="0.05"/>
      </geometry>
      <material name="black_left">
        <color rgba="0.1 0.1 0.1 1"/>
      </material>
    </visual>
    <collision>
      <geometry>
        <cylinder length="0.04" radius="0.05"/>
      </geometry>
    </collision>
    <inertial>
      <origin rpy="0 0 0" xyz="0 0 0"/>
      <mass value="0.1"/>
      <inertia ixx="7.583333333333335e-05" ixy="0.0" ixz="0.0" iyy="7.583333333333335e-05" iyz="0.0" izz="0.00012500000000000003"/>
    </inertial>
  </link>
  <link name="right_wheel">
    <visual>
      <geometry>
        <cylinder length="0.04" radius="0.05"/>
      </geometry>
      <material name="black_right">
        <color rgba="0.1 0.1 0.1 1"/>
      </material>
    </visual>
    <collision>
      <geometry>
        <cylinder length="0.04" radius="0.05"/>
      </geometry>
    </collision>
    <inertial>
      <origin rpy="0 0 0" xyz="0 0 0"/>
      <mass value="0.1"/>
      <inertia ixx="7.583333333333335e-05" ixy="0.0" ixz="0.0" iyy="7.583333333333335e-05" iyz="0.0" izz="0.00012500000000000003"/>
    </inertial>
  </link>
  <link name="front_caster">
    <visual>
      <geometry>
        <sphere radius="0.05"/>
      </geometry>
    </visual>
    <collision>
      <geometry>
        <sphere radius="0.05"/>
      </geometry>
    </collision>
    <inertial>
      <origin rpy="0 0 0" xyz="0 0 0"/>
      <mass value="0.1"/>
      <inertia ixx="0.00010000000000000005" ixy="0.0" ixz="0.0" iyy="0.00010000000000000005" iyz="0.0" izz="0.00010000000000000005"/>
    </inertial>
  </link>
  <!-- Joints -->
  <joint name="chassis_joint" type="fixed">
    <parent link="base_link"/>
    <child link="chassis"/>
    <origin xyz="-0.1 0 0"/>
  </joint>
  <joint name="left_wheel_joint" type="continuous">
    <parent link="base_link"/>
    <child link="left_wheel"/>
    <origin rpy="-1.5708 0 0" xyz="0 0.175 0"/>
    <axis xyz="0 0 1"/>
  </joint>
  <joint name="right_wheel_joint" type="continuous">
    <parent link="base_link"/>
    <child link="right_wheel"/>
    <origin rpy="1.5708 0 0" xyz="0 -0.175 0"/>
    <axis xyz="0 0 -1"/>
  </joint>
  <joint name="front_caster_joint" type="fixed">
    <parent link="chassis"/>
    <child link="front_caster"/>
    <origin xyz="0.64 0 0"/>
  </joint>
  <!-- Gazebo scripted material on links (use file:// URI passed from launch; safe with spaces) -->
  <!--<gazebo reference="chassis">
    <material>
      <script>
        <uri>${pkg_uri}/models/goal_marker/materials/scripts</uri>
        <uri>${pkg_uri}/models/goal_marker/materials/textures</uri>
        <name>goal_marker/ChassisPattern</name>
      </script>
    </material>
  </gazebo>

  <gazebo reference="base_link">
    <material>
      <script>
        <uri>${pkg_uri}/models/goal_marker/materials/scripts</uri>
        <uri>${pkg_uri}/models/goal_marker/materials/textures</uri>
        <name>goal_marker/ChassisPattern</name>
      </script>
    </material>
  </gazebo>-->
  <gazebo reference="chassis">
    <material>
      <pbr>
        <metal>
          <albedo_map>package://goal_marker_description/models/goal_marker/materials/textures/pattern.png</albedo_map>
          <metalness>0.1</metalness>
          <roughness>0.5</roughness>
        </metal>
      </pbr>
    </material>
  </gazebo>
  <gazebo reference="base_link">
    <material>
      <pbr>
        <metal>
          <albedo_map>package://goal_marker_description/models/goal_marker/materials/textures/pattern.png</albedo_map>
          <metalness>0.1</metalness>
          <roughness>0.5</roughness>
        </metal>
      </pbr>
    </material>
  </gazebo>
  <!-- Other Gazebo materials -->
  <gazebo reference="left_wheel">
    <material>Gazebo/Grey</material>
  </gazebo>
  <gazebo reference="right_wheel">
    <material>Gazebo/Grey</material>
  </gazebo>
  <gazebo reference="front_caster">
    <material>Gazebo/Black</material>
  </gazebo>
  <!-- Plugin -->
  <gazebo>
    <plugin filename="libgazebo_ros_diff_drive.so" name="goal_diff_drive">
      <ros>
        <namespace>/goal_marker</namespace>
        <remapping>cmd_vel:=/goal_marker/cmd_vel</remapping>
        <remapping>odom:=/goal_marker/odom</remapping>
      </ros>
      <left_joint>left_wheel_joint</left_joint>
      <right_joint>right_wheel_joint</right_joint>
      <wheel_separation>0.35</wheel_separation>
      <wheel_diameter>0.1</wheel_diameter>
      <max_wheel_torque>20</max_wheel_torque>
      <max_wheel_acceleration>5.0</max_wheel_acceleration>
      <publish_odom>true</publish_odom>
      <publish_wheel_tf>false</publish_wheel_tf>
      <publish_odom_tf>false</publish_odom_tf>
      <odometry_frame>goal_odom</odometry_frame>
      <robot_base_frame>chassis</robot_base_frame>
    </plugin>
  </gazebo>
</robot>
