<?xml version="1.0"?>
<robot name="goal_marker" xmlns:xacro="http://www.ros.org/wiki/xacro">

  <xacro:include filename="inertial_macros.xacro"/>

  <!-- Root -->
  <link name="base_link">
  </link>

  <!-- Base box -->
  <link name="chassis">
    
    <visual>
      <origin xyz="0.15 0 0.075"/>
      <geometry>
        <box size="0.3 0.3 0.15"/>
      </geometry>
      <material name="green"><color rgba="0 1 0 1"/></material>
    </visual>
    
    <collision>
      <origin xyz="0.15 0 0.075"/>
      <geometry>
        <box size="0.3 0.3 0.15"/>
      </geometry>
    </collision>

    <xacro:inertial_box mass="0.5" x="0.3" y="0.3" z="0.15">
      <origin xyz="0.15 0 0.075" rpy="0 0 0"/>
    </xacro:inertial_box>

  </link>

  <!-- Wheels (cylinders roll about +Y) -->
  <link name="left_wheel">
    <visual>
      <geometry><cylinder length="0.04" radius="0.05"/></geometry>
      <material name="black_left"><color rgba="0.1 0.1 0.1 1"/></material>
    </visual>
    <collision>
      <geometry><cylinder length="0.04" radius="0.05"/></geometry>
    </collision>
    <xacro:inertial_cylinder mass="0.1" length="0.04" radius="0.05">
      <origin xyz="0 0 0" rpy="0 0 0"/>
    </xacro:inertial_cylinder>
  </link>

  <link name="right_wheel">
    <visual>
      <geometry><cylinder length="0.04" radius="0.05"/></geometry>
      <material name="black_right"><color rgba="0.1 0.1 0.1 1"/></material>
    </visual>
    <collision>
      <geometry><cylinder length="0.04" radius="0.05"/></geometry>
    </collision>
    <xacro:inertial_cylinder mass="0.1" length="0.04" radius="0.05">
      <origin xyz="0 0 0" rpy="0 0 0"/>
    </xacro:inertial_cylinder>
  </link>

  <!-- Caster (fixed sphere for stability) -->
  <link name="front_caster">
    <visual><geometry><sphere radius="0.05"/></geometry></visual>
    <collision><geometry><sphere radius="0.05"/></geometry></collision>
    <xacro:inertial_sphere mass="0.1" radius="0.05">
      <origin xyz="0 0 0" rpy="0 0 0"/>
    </xacro:inertial_sphere>
  </link>

  <!-- Joints -->
  <joint name="chassis_joint" type="fixed">
    <parent link="base_link"/>
    <child link="chassis"/>
    <origin xyz="-0.1 0 0"/>
  </joint>

  <joint name="left_wheel_joint" type="continuous">
    <parent link="base_link"/>
    <child link="left_wheel"/>
    <origin xyz="0 0.175 0" rpy="-1.5708 0 0"/>
    <axis xyz="0 0 1"/>
    <!--<dynamics damping="3.0" friction="0.3"/>-->
  </joint>

  <joint name="right_wheel_joint" type="continuous">
    <parent link="base_link"/>
    <child link="right_wheel"/>
    <origin xyz="0 -0.175 0" rpy="1.5708 0 0"/>
    <axis xyz="0 0 -1"/>
    <!--<dynamics damping="3.0" friction="0.3"/>-->
  </joint>

  <joint name="front_caster_joint" type="fixed">
    <parent link="chassis"/>
    <child link="front_caster"/>
    <origin xyz="0.24 0 0"/> 
  </joint>

  <!-- Gazebo extensions: put contact/friction here, NOT in URDF collisions -->
  <gazebo reference="chassis">
    <material>Gazebo/Green</material>
    <mu1>0.2</mu1><mu2>0.2</mu2>
  </gazebo>
  <gazebo reference="left_wheel">
    <material>Gazebo/Black</material>
    <mu1>1.2</mu1><mu2>1.2</mu2>
  </gazebo>
  <gazebo reference="right_wheel">
    <material>Gazebo/Black</material>
    <mu1>1.2</mu1><mu2>1.2</mu2>
  </gazebo>
  <gazebo reference="front_caster">
    <mu1>0.1</mu1><mu2>0.1</mu2>
  </gazebo>

  <!-- Diff-drive plugin -->
  <gazebo>
    <plugin name="goal_diff_drive" filename="libgazebo_ros_diff_drive.so">
      <ros>
        <namespace>/goal_marker</namespace>
        <remapping>cmd_vel:=/goal_marker/cmd_vel</remapping>
        <remapping>odom:=/goal_marker/odom</remapping>
      </ros>
      <left_joint>left_wheel_joint</left_joint>
      <right_joint>right_wheel_joint</right_joint>
      <wheel_separation>0.35</wheel_separation>
      <wheel_diameter>0.1</wheel_diameter>
      <max_wheel_torque>20</max_wheel_torque>
      <max_wheel_acceleration>5.0</max_wheel_acceleration>
      <publish_odom>true</publish_odom>
      <publish_wheel_tf>false</publish_wheel_tf>
      <publish_odom_tf>false</publish_odom_tf>
      <odometry_frame>goal_odom</odometry_frame>
      <robot_base_frame>chassis</robot_base_frame>
    </plugin>
  </gazebo>

</robot>